Workbook

Sheet resumen mensual
A1: TC | B1: 1200 | C1: 1094 | D1: 1104 | E1: 1197 | F1: 1210 | G1: 1217 | H1: 1386 | I1: 1363 | J1: 1381 | K1: 1490
A2: TOTALES | O2: DÍAS DEL MES | P2: 29
A3: Métrica / fecha | B3: ENERO | C3: FEBRERO | D3: MARZO | E3: ABRIL | F3: MAYO | G3: JUNIO | H3: JULIO | I3: AGOSTO | J3: SEPTIEMBRE | K3: OCTUBRE | L3: NOVIEMBRE | M3: DICIEMBRE | N3: PROMEDIOS | O3: OBJETIVO | P3: PROYECCIÓN
A4: Inversión total | B4: =148000+5495437 -> 5643437 | C4: =102000+5408210 -> 5510210 | D4: =151000+6321878 -> 6472878 | E4: =131000+5955786 -> 6086786 | F4: =221000+6432636 -> 6653636 | G4: =254000+8395732 -> 8649732 | H4: =316000+9967250 -> 10283250 | I4: =Agosto_25!G4 -> 6744969 | J4: =Septiembre_25!G4 -> 7369795 | K4: =Octubre_25!G4 -> 8670544 | L4: =Noviembre_25!G4 -> 7375151 | M4: =Diciembre_25!G4 -> 9443898 | N4: =AVERAGE(B4:M4) -> 7408690.5 | O4: 8550000 | P4: =L4/$P$2*30 -> 7629466.6
A5: Inv USD | B5: =B4/B$1 -> 4702.8642 | C5: =C4/C$1 -> 5036.755 | D5: =D4/D$1 -> 5863.1141 | E5: =E4/E$1 -> 5085.0343 | F5: =F4/F$1 -> 5498.8727 | G5: =G4/G$1 -> 7107.4215 | H5: =H4/H$1 -> 7419.3723 | I5: =I4/I$1 -> 4948.62 | J5: =J4/J$1 -> 5336.5641 | K5: =Octubre_25!G5 -> 5819.157 | L5: =Noviembre_25!G5 -> 4949.7658 | M5: =Diciembre_25!G5 -> 6338.1866 | N5: =AVERAGE(B5:M5) -> 5675.4773 | O5: =O4/$B$1 -> 7125 | P5: =P4/$J$1 -> 5524.5956
A6: Leads Ingresados | B6: =2325+171+18 -> 2514 | C6: =2269+25+108 -> 2402 | D6: =2768+17+184 -> 2969 | E6: 2929 | F6: 1377 | G6: 1387 | H6: 2163 | I6: =Agosto_25!G5 -> 1155 | J6: =Septiembre_25!G6 -> 1573 | K6: =Octubre_25!G6 -> 1799 | L6: =Noviembre_25!G6 -> 2263 | M6: =Diciembre_25!G6 -> 2565 | N6: =AVERAGE(B6:M6) -> 2091.3333 | O6: 1632 | P6: =L6/$P$2*30 -> 2341.0345
A7: CPL | B7: =B4/B6 -> 2244.8039 | C7: =C4/C6 -> 2294.0092 | D7: =D4/D6 -> 2180.1543 | E7: =E4/E6 -> 2078.1106 | F7: =F4/F6 -> 4831.9797 | G7: =G4/G6 -> 6236.2884 | H7: =H4/H6 -> 4754.1609 | I7: =I4/I6 -> 5839.8 | J7: =Septiembre_25!G7 -> 4685.1844 | K7: =Octubre_25!G7 -> 4819.6465 | L7: =Noviembre_25!G7 -> 3259.015 | M7: =Diciembre_25!G7 -> 3681.8316 | N7: =AVERAGE(B7:M7) -> 3908.7487 | O7: =O4/O6 -> 5238.9706 | P7: =P4/P6 -> 3259.015
A8: CPL USD | B8: =B7/B$1 -> 1.8706699 | C8: =C7/C$1 -> 2.0969005 | D8: =D7/D$1 -> 1.9747774 | E8: =E7/E$1 -> 1.7360991 | F8: =F7/F$1 -> 3.9933716 | G8: =G7/G$1 -> 5.1243126 | H8: =H7/H$1 -> 3.4301305 | I8: =I7/I$1 -> 4.2845194 | J8: =J7/J$1 -> 3.3926027 | K8: =Octubre_25!G8 -> 3.2346621 | L8: =Noviembre_25!G8 -> 2.1872584 | M8: =Diciembre_25!G8 -> 2.4710279 | N8: =AVERAGE(B8:M8) -> 2.9830277 | O8: =O5/O$6 -> 4.3658088
A9: Reuniones | B9: 198 | C9: 204 | D9: 134 | E9: 99 | F9: 127 | G9: 124 | H9: 158 | I9: 125 | J9: 160 | K9: =Octubre_25!G9 -> 160 | L9: =Noviembre_25!G9 -> 132 | M9: =Diciembre_25!G9 -> 161 | N9: =AVERAGE(B9:M9) -> 148.5 | O9: 157 | P9: =L9/$P$2*30 -> 136.55172
A10: CPR | B10: =B4/B9 -> 28502.207 | C10: =C4/C9 -> 27010.833 | D10: =D4/D9 -> 48305.06 | E10: =E4/E9 -> 61482.687 | F10: =F4/F9 -> 52390.835 | G10: =G4/G9 -> 69755.903 | H10: =H4/H9 -> 65083.861 | I10: =I4/I9 -> 53959.752 | J10: =Septiembre_25!G11 -> 51537.028 | K10: =Octubre_25!G11 -> 54190.9 | L10: =Noviembre_25!G11 -> 55872.356 | M10: =Diciembre_25!G11 -> 58657.752 | N10: =AVERAGE(B10:M10) -> 52229.098 | O10: =O4/O9 -> 54458.599 | P10: =P4/P9 -> 55872.356
A11: CPR USD | B11: =B10/B$1 -> 23.751839 | C11: =C10/C$1 -> 24.689976 | D11: =D10/D$1 -> 43.754583 | E11: =E10/E$1 -> 51.363982 | F11: =F10/F$1 -> 43.29821 | G11: =G10/G$1 -> 57.317916 | H11: =H10/H$1 -> 46.958053 | I11: =I10/I$1 -> 39.58896 | J11: =J10/J$1 -> 37.31863 | K11: =Octubre_25!G12 -> 36.369732 | L11: =Noviembre_25!G12 -> 37.498226 | M11: =Diciembre_25!G12 -> 39.367618 | N11: =AVERAGE(B11:M11) -> 40.106477 | O11: =O5/O$9 -> 45.382166
A12: % Lead a reunión | B12: =B9/B6 -> 0.07875895 | C12: =C9/C6 -> 0.084929226 | D12: =D9/D6 -> 0.045133041 | E12: =E9/E6 -> 0.033799932 | F12: =F9/F6 -> 0.092229484 | G12: =G9/G6 -> 0.089401586 | H12: =H9/H6 -> 0.073046694 | I12: =I9/I6 -> 0.10822511 | J12: =Septiembre_25!G13 -> 0.10298792 | K12: =Octubre_25!G13 -> 0.088938299 | L12: =Noviembre_25!G13 -> 0.058329651 | M12: =Diciembre_25!G13 -> 0.062768031 | N12: =AVERAGE(B12:M12) -> 0.07654566 | O12: =O9/O6 -> 0.09620098 | P12: =P9/P6 -> 0.058329651
A13: Cierres | B13: 8.5 | C13: 6.3 | D13: 6.6 | E13: 11 | F13: 4.6 | G13: 5.6 | H13: 10.8 | I13: 4 | J13: 8.3 | K13: 5.5 | L13: 0.8 | M13: =Diciembre_25!G18 -> 5 | N13: =AVERAGE(B13:M13) -> 6.4166667
A14: CP_CIERRE | B14: =B4/B13 -> 663933.76 | C14: =C4/C13 -> 874636.51 | D14: =D4/D13 -> 980739.09 | E14: =E4/E13 -> 553344.18 | F14: =F4/F13 -> 1446442.6 | G14: =G4/G13 -> 1544595 | H14: =H4/H13 -> 952152.78 | I14: =I4/I13 -> 1686242.2 | J14: =Septiembre_25!G15 -> 1473959 | K14: =K4/K13 -> 1576462.5 | L14: =L4/L13 -> 9218938.8 | M14: =M4/M13 -> 1888779.6 | N14: =AVERAGE(B14:M14) -> 1905018.8
A15: CPC USD | B15: =B14/B$1 -> 553.27814 | C15: =C14/C$1 -> 799.48492 | D15: =D14/D$1 -> 888.35063 | E15: =E14/E$1 -> 462.27584 | F15: =F14/F$1 -> 1195.4071 | G15: =G14/G$1 -> 1269.1824 | H15: =H14/H$1 -> 686.97892 | I15: =I14/I$1 -> 1237.155 | ... K15: =K14/K$1 -> 1058.0286 | L15: =L14/K$1 -> 6187.2072 | M15: =M14/K$1 -> 1267.6373 | N15: =AVERAGE(B15:M15) -> 1389.3582
A16: CIERRES TOTALES | C16: 14.6 | D16: 9.5 | E16: 8.3 | F16: 13.7 | G16: 5.6 | H16: 12.5 | I16: 5.8 | J16: 10.55 | K16: 7.75 | L16: 2.45 | M16: 8.95 | N16: =AVERAGE(B16:M16) -> 9.0636364
A17: % lead a cierre | B17: =B13/B6 -> 0.003381066 | C17: =C13/C6 -> 0.0026228143 | D17: =D13/D6 -> 0.0022229707 | E17: =E13/E6 -> 0.003755548 | F17: =F13/F6 -> 0.0033405955 | G17: =G13/G6 -> 0.004037491 | H17: =H13/H6 -> 0.0049930652 | I17: =I13/I6 -> 0.0034632035 | J17: =Septiembre_25!G17 -> 0.0031786395 | K17: =K13/K6 -> 0.003057254 | L17: =L13/L6 -> 0.00035351304 | M17: =M13/M6 -> 0.0019493177 | N17: =AVERAGE(B17:I17) -> 0.0034770943
A18: % reunión a cierre | B18: =B13/B9 -> 0.042929293 | C18: =C13/C9 -> 0.030882353 | D18: =D13/D9 -> 0.049253731 | E18: =E13/E9 -> 0.11111111 | F18: =F13/F9 -> 0.036220472 | G18: =G13/G9 -> 0.04516129 | H18: =H13/H9 -> 0.06835443 | I18: =I13/I9 -> 0.032 | ... N18: =N13/N9 -> 0.043209877
B20: Proyección septiembre | C20: PROYECCIÓN SEPTIEMBRE
B23: 1.5

Sheet Enero_26
A1: TC | B1: 1490 | F1: DIA | G1: 19 | H1: % DEL MES | I1: =G1/30 -> 0.63333333
A2: TOTALES
A3: Métrica / fecha | B3: 01/01 al 06/01 | C3: 07/01 al 13/01 | D3: 14/01 al 20/01 | E3: 21/01 al 27/01 | F3: 28/01 al 31/01 | G3: TOTAL | H3: OBJETIVO | I3: % DE LOGRO | J3: PROYECC | K3: .
A4: Inversión total | B4: =1653946+88523 -> 1742469 | C4: =1774569+105128 -> 1879697 | D4: =1856984+96067 -> 1953051 | G4: =SUM(B4:F4) -> 5575217 | H4: 8850000 | I4: =G4/H4 -> 0.62996802 | J4: =$G4/$G$1*30 -> 8802974.2
A5: Inv USD | B5: =B4/$B$1 -> 1169.4423 | C5: =C4/$B$1 -> 1261.5416 | D5: =D4/$B$1 -> 1310.7725 | E5: =E4/$B$1 -> 0 | F5: =F4/$B$1 -> 0 | G5: =SUM(B5:F5) -> 3741.7564 | H5: =H4/$B$1 -> 5939.5973 | I5: =G5/H5 -> 0.62996802 | J5: =J4/$B$1 -> 5908.0364
A6: Leads Ingresados | B6: 464 | C6: 533 | D6: 444 | G6: =SUM(B6:F6) -> 1441 | H6: 2008 | I6: =G6/H6 -> 0.71762948 | J6: =$G6/$G$1*30 -> 2275.2632
A7: CPL | B7: =B4/B6 -> 3755.3211 | C7: =C4/C6 -> 3526.636 | D7: =D4/D6 -> 4398.7635 | E7: =E4/E6 -> #DIV/0! | F7: =F4/F6 -> #DIV/0! | G7: =G4/$G$6 -> 3868.9917 | H7: =H4/H6 -> 4407.3705 | I7: =H7/G7-1 -> 0.13915224 | J7: =J4/J6 -> 3868.9917
A8: CPL USD | B8: =B7/$B$1 -> 2.5203497 | C8: =C7/$B$1 -> 2.3668698 | D8: =D7/$B$1 -> 2.9521903 | E8: =E7/$B$1 -> #DIV/0! | F8: =F7/$B$1 -> #DIV/0! | G8: =G5/G$6 -> 2.5966387 | H8: =H5/H$6 -> 2.9579668
A9: Reuniones agendadas | B9: 38 | C9: 36 | D9: 36 | G9: =SUM(B9:F9) -> 110 | H9: 160 | I9: =G9/H9 -> 0.6875 | J9: =$G9/$G$1*30 -> 173.68421
A10: Reuniones efectivas | B10: =B9-6 -> 32 | C10: =C9-8 -> 28 | D10: 21 | G10: =SUM(B10:F10) -> 81
A11: CPR | B11: =B4/B9 -> 45854.447 | C11: =C4/C9 -> 52213.806 | D11: =D4/D9 -> 54251.417 | E11: =E4/E9 -> #DIV/0! | F11: =F4/F9 -> #DIV/0! | G11: =G4/G$9 -> 50683.791 | H11: =H4/H9 -> 55312.5 | J11: =J4/J9 -> 50683.791
A12: CPR USD | B12: =B11/$B$1 -> 30.774797 | C12: =C11/$B$1 -> 35.042823 | D12: =D11/$B$1 -> 36.410347 | E12: =E11/$B$1 -> #DIV/0! | F12: =F11/$B$1 -> #DIV/0! | G12: =G5/G$9 -> 34.015967 | H12: =H5/H$9 -> 37.122483
A13: % Lead a reunión | B13: =B9/B6 -> 0.081896552 | C13: =C9/C6 -> 0.067542214 | D13: =D9/D6 -> 0.081081081 | E13: =E9/E6 -> #DIV/0! | F13: =F9/F6 -> #DIV/0! | G13: =G9/G6 -> 0.076335878 | H13: =H9/H6 -> 0.079681275 | J13: =J9/J6 -> 0.076335878
A14: Embudo | B14: 3 | C14: 1 | D14: 3 | G14: =SUM(B14:F14) -> 7
A15: CPE | B15: =B4/B14 -> 580823 | C15: =C4/C14 -> 1879697 | D15: =D4/D14 -> 651017 | E15: =E4/E14 -> #DIV/0! | F15: =F4/F14 -> #DIV/0! | G15: =G4/G14 -> 796459.57
A16: CPE USD | B16: =B15/$B$1 -> 389.81409 | C16: =C15/$B$1 -> 1261.5416 | D16: =D15/$B$1 -> 436.92416 | E16: =E15/$B$1 -> #DIV/0! | F16: =F15/$B$1 -> #DIV/0! | G16: =G15/$B$1 -> 534.53663
A17: % Lead a embudo | B17: =B14/B6 -> 0.0064655172 | C17: =C14/C6 -> 0.0018761726 | D17: =D14/D6 -> 0.0067567568 | E17: =E14/E6 -> #DIV/0! | F17: =F14/F6 -> #DIV/0! | G17: =G14/G6 -> 0.0048577377
A18: Cierres | D18: 2.5 | G18: =SUM(B18:F18) -> 2.5 | J18: =$G18/$G$1*30 -> 3.9473684
A19: Costo por Cierre | B19: =B5/B18 -> #DIV/0! | C19: =C4/C18 -> #DIV/0! | D19: 100 | E19: =E4/E18 -> #DIV/0! | F19: =F4/F18 -> #DIV/0! | G19: =G4/G$18 -> 2230086.8 | J19: =J4/J18 -> 2230086.8
A20: CPC USD | B20: =B19/$B$1 -> #DIV/0! | C20: =C19/$B$1 -> #DIV/0! | D20: =D19/$B$1 -> 0.067114094 | E20: =E19/$B$1 -> #DIV/0! | F20: =F19/$B$1 -> #DIV/0! | G20: =G5/G$18 -> 1496.7025
A21: % lead a cierre | B21: =B18/B6 -> 0 | C21: =C18/C6 -> 0 | D21: =D18/D6 -> 0.0056306306 | E21: =E18/E6 -> #DIV/0! | F21: =F18/F6 -> #DIV/0! | G21: =G18/G6 -> 0.0017349063 | J21: =J18/J6 -> 0.0017349063
A23: CORRALONES
A24: Métrica / fecha | B24: 01/01 al 06/01 | C24: 07/01 al 13/01 | D24: 14/01 al 20/01 | E24: 21/01 al 27/01 | F24: 28/01 al 31/01 | G24: TOTAL | H24: OBJETIVO | I24: PROYECC
A25: Inversión total | B25: =119987+302930 -> 422917 | C25: =164508+357076 -> 521584 | G25: =SUM(B25:F25) -> 944501 | H25: =B169 -> 2100000 | I25: =$G25/$G$1*30 -> 1491317.4 | J25: =(H25-G25)/15 -> 77033.267
A26: Inv USD | B26: =B25/$B$1 -> 283.83691 | C26: =C25/$B$1 -> 350.05638 | D26: =D25/$B$1 -> 0 | E26: =E25/$B$1 -> 0 | F26: =F25/$B$1 -> 0 | G26: =SUM(B26:F26) -> 633.89329 | H26: =H25/$B$1 -> 1409.396 | I26: =I25/$B$1 -> 1000.8841 | J26: =H26/$H$5 -> 0.23728814
A27: Leads Ingresados | B27: 62 | C27: 51 | G27: =SUM(B27:F27) -> 113 | H27: =B172 -> 381.81818 | I27: =$G27/$G$1*30 -> 178.42105
A28: CPL | B28: =B25/B27 -> 6821.2419 | C28: =C25/C27 -> 10227.137 | D28: =D25/D27 -> #DIV/0! | E28: =E25/E27 -> #DIV/0! | F28: =F25/F27 -> #DIV/0! | G28: =G25/G$27 -> 8358.4159 | H28: =H25/H27 -> 5500 | I28: =I25/I27 -> 8358.4159
A29: CPL USD | B29: =B28/$B$1 -> 4.5780147 | C29: =C28/$B$1 -> 6.8638505 | D29: =D28/$B$1 -> #DIV/0! | E29: =E28/$B$1 -> #DIV/0! | F29: =F28/$B$1 -> #DIV/0! | G29: =G26/G$27 -> 5.6096751 | H29: =H28/$B$1 -> 3.6912752 | I29: =I28/$B$1 -> 5.6096751
A30: Reuniones | B30: 8 | C30: 6 | G30: =SUM(B30:F30) -> 14 | H30: =B174 -> 38.181818 | I30: =$G30/$G$1*30 -> 22.105263
A31: CPR | B31: =B25/B30 -> 52864.625 | C31: =C25/C30 -> 86930.667 | D31: =D25/D30 -> #DIV/0! | E31: =E25/E30 -> #DIV/0! | F31: =F25/F30 -> #DIV/0! | G31: =G25/G$30 -> 67464.357 | H31: =H25/H30 -> 55000 | I31: =I25/I30 -> 67464.357
A32: CPR USD | B32: =B31/$B$1 -> 35.479614 | C32: =C31/$B$1 -> 58.342729 | D32: =D31/$B$1 -> #DIV/0! | E32: =E31/$B$1 -> #DIV/0! | F32: =F31/$B$1 -> #DIV/0! | G32: =G26/G$30 -> 45.278092 | H32: =H31/$B$1 -> 36.912752 | I32: =I31/$B$1 -> 45.278092
A33: % Lead a reunión | B33: =B30/B27 -> 0.12903226 | C33: =C30/C27 -> 0.11764706 | D33: =D30/D27 -> #DIV/0! | E33: =E30/E27 -> #DIV/0! | F33: =F30/F27 -> #DIV/0! | G33: =G30/G27 -> 0.12389381 | H33: =H30/H27 -> 0.1 | I33: =I30/I27 -> 0.12389381
A34: Cierres | G34: =SUM(B34:D34) -> 0 | I34: =$G34/$G$1*30 -> 0
A35: CP_CIERRE | I35: =I25/I34 -> #DIV/0!
A36: CPC USD | B36: =B35/$B$1 -> 0 | C36: =C35/$B$1 -> 0 | D36: =D35/$B$1 -> 0
A37: % lead a cierre | I37: =I34/I27 -> 0
A40: DISTRIBUIDORA
A41: Métrica / fecha | B41: 01/01 al 06/01 | C41: 07/01 al 13/01 | D41: 14/01 al 20/01 | E41: 21/01 al 27/01 | F41: 28/01 al 31/01 | G41: TOTAL | H41: OBJETIVO | I41: PROYECC
A42: Inversión total | B42: =123204+181007 -> 304211 | C42: =229423+164839 -> 394262 | G42: =SUM(B42:F42) -> 698473 | H42: =C169 -> 2100000 | I42: =$G42/$G$1*30 -> 1102852.1 | J42: =(H42-G42)/15 -> 93435.133
A43: Inv USD | B43: =B42/$B$1 -> 204.16846 | C43: =C42/$B$1 -> 264.60537 | D43: =D42/$B$1 -> 0 | E43: =E42/$B$1 -> 0 | F43: =F42/$B$1 -> 0 | G43: =SUM(B43:F43) -> 468.77383 | H43: =H42/$B$1 -> 1409.396 | J43: =H43/$H$5 -> 0.23728814
...

Sheet Diciembre_25
A1: TC | B1: 1490 | F1: DIA | G1: 29 | H1: % DEL MES | I1: =G1/30 -> 0.96666667
A2: TOTALES
A3: Métrica / fecha | B3: 01/12 al 02/12 | C3: 03/12 al 09/12 | D3: 10/12 al 16/12 | E3: 17/12 al 23/12 | F3: 24/12 al 31/12 | G3: TOTAL | H3: OBJETIVO | I3: % DE LOGRO | J3: PROYECC | K3: .
A4: Inversión total | B4: 803321 | C4: 1910590 | D4: 2312526 | E4: =2189139+252580 -> 2441719 | F4: =1804914+170828 -> 1975742 | G4: =SUM(B4:F4) -> 9443898 | H4: 8850000 | I4: =G4/H4 -> 1.0671071 | J4: =$G4/$G$1*30 -> 9769549.7
A5: Inv USD | B5: =B4/$B$1 -> 539.14161 | C5: =C4/$B$1 -> 1282.2752 | D5: =D4/$B$1 -> 1552.0309 | E5: =E4/$B$1 -> 1638.7376 | F5: =F4/$B$1 -> 1326.0013 | G5: =SUM(B5:F5) -> 6338.1866 | H5: =H4/$B$1 -> 5939.5973 | I5: =G5/H5 -> 1.0671071 | J5: =J4/$B$1 -> 6556.7447
A6: Leads Ingresados | B6: 280 | C6: 600 | D6: 662 | E6: 530 | F6: 493 | G6: =SUM(B6:F6) -> 2565 | H6: 2008 | I6: =G6/H6 -> 1.2773904 | J6: =$G6/$G$1*30 -> 2653.4483
A7: CPL | B7: =B4/B6 -> 2869.0036 | C7: =C4/C6 -> 3184.3167 | D7: =D4/D6 -> 3493.2417 | E7: =E4/E6 -> 4607.017 | F7: =F4/F6 -> 4007.5903 | G7: =G4/$G$6 -> 3681.8316 | H7: =H4/H6 -> 4407.3705 | I7: =H7/G7-1 -> 0.19705924 | J7: =J4/J6 -> 3681.8316
A8: CPL USD | B8: =B7/$B$1 -> 1.9255058 | C8: =C7/$B$1 -> 2.1371253 | D8: =D7/$B$1 -> 2.3444575 | E8: =E7/$B$1 -> 3.0919577 | F8: =F7/$B$1 -> 2.6896579 | G8: =G5/G$6 -> 2.4710279 | H8: =H5/H$6 -> 2.9579668
A9: Reuniones agendadas | B9: 11 | C9: 33 | D9: 52 | E9: 31 | F9: 34 | G9: =SUM(B9:F9) -> 161 | H9: 160 | I9: =G9/H9 -> 1.00625 | J9: =$G9/$G$1*30 -> 166.55172
A10: Reuniones efectivas | B10: 10 | C10: 26 | D10: 37 | E10: 20 | F10: 14 | G10: =SUM(B10:F10) -> 107
A11: CPR | B11: =B4/B9 -> 73029.182 | C11: =C4/C9 -> 57896.667 | D11: =D4/D9 -> 44471.654 | E11: =E4/E9 -> 78765.129 | F11: =F4/F9 -> 58110.059 | G11: =G4/G$9 -> 58657.752 | H11: =H4/H9 -> 55312.5 | J11: =J4/J9 -> 58657.752
A12: CPR USD | B12: =B11/$B$1 -> 49.012874 | C12: =C11/$B$1 -> 38.856823 | D12: =D11/$B$1 -> 29.846748 | E12: =E11/$B$1 -> 52.862503 | F12: =F11/$B$1 -> 39.000039 | G12: =G5/G$9 -> 39.367618 | H12: =H5/H$9 -> 37.122483
A13: % Lead a reunión | B13: =B9/B6 -> 0.039285714 | C13: =C9/C6 -> 0.055 | D13: =D9/D6 -> 0.078549849 | E13: =E9/E6 -> 0.058490566 | F13: =F9/F6 -> 0.068965517 | G13: =G9/G6 -> 0.062768031 | H13: =H9/H6 -> 0.079681275 | J13: =J9/J6 -> 0.062768031
A14: Embudo | B14: 0 | C14: 2 | D14: 10 | E14: 6 | F14: 5 | G14: =SUM(B14:F14) -> 23
A15: CPE | B15: =B4/B14 -> #DIV/0! | C15: =C4/C14 -> 955295 | D15: =D4/D14 -> 231252.6 | E15: =E4/E14 -> 406953.17 | F15: =F4/F14 -> 395148.4 | G15: =G4/G14 -> 410604.26
A16: CPE USD | B16: =B15/$B$1 -> #DIV/0! | C16: =C15/$B$1 -> 641.13758 | D16: =D15/$B$1 -> 155.20309 | E16: =E15/$B$1 -> 273.12293 | F16: =F15/$B$1 -> 265.20027 | G16: =G15/$B$1 -> 275.57333
A17: % Lead a embudo | B17: =B14/B6 -> 0 | C17: =C14/C6 -> 0.0033333333 | D17: =D14/D6 -> 0.01510574 | E17: =E14/E6 -> 0.011320755 | F17: =F14/F6 -> 0.010141988 | G17: =G14/G6 -> 0.0089668616
A18: Cierres | C18: 1 | D18: 2 | E18: 1 | F18: 1 | G18: =SUM(B18:F18) -> 5 | J18: =$G18/$G$1*30 -> 5.1724138
A19: Costo por Cierre | B19: =B5/B18 -> #DIV/0! | C19: =C4/C18 -> 1910590 | D19: =D4/D18 -> 1156263 | E19: =E4/E18 -> 2441719 | F19: =F4/F18 -> 1975742 | G19: =G4/G$18 -> 1888779.6 | J19: =J4/J18 -> 1888779.6
A20: CPC USD | B20: =B19/$B$1 -> #DIV/0! | C20: =C19/$B$1 -> 1282.2752 | D20: =D19/$B$1 -> 776.01544 | E20: =E19/$B$1 -> 1638.7376 | F20: =F19/$B$1 -> 1326.0013 | G20: =G5/G$18 -> 1267.6373
A21: % lead a cierre | B21: =B18/B6 -> 0 | C21: =C18/C6 -> 0.0016666667 | D21: =D18/D6 -> 0.003021148 | E21: =E18/E6 -> 0.0018867925 | F21: =F18/F6 -> 0.0020283976 | G21: =G18/G6 -> 0.0019493177 | J21: =J18/J6 -> 0.0019493177
A23: CORRALONES
A24: Métrica / fecha | B24: =B3 -> 01/12 al 02/12 | C24: =C3 -> 03/12 al 09/12 | D24: =D3 -> 10/12 al 16/12 | E24: =E3 -> 17/12 al 23/12 | F24: =F3 -> 24/12 al 31/12 | G24: TOTAL | H24: OBJETIVO | I24: PROYECC
A25: Inversión total | B25: =85289+71155 -> 156444 | C25: =9283+418792 -> 428075 | D25: =115390+25741+421101 -> 562232 | E25: =115531+25741+421161 -> 562433 | F25: =57981+350461 -> 408442 | G25: =SUM(B25:F25) -> 2117626 | H25: =B169 -> 2100000 | I25: =$G25/$G$1*30 -> 2190647.6 | J25: =(H25-G25)/15 -> -1175.0667
A26: Inv USD | B26: =B25/$B$1 -> 104.99597 | C26: =C25/$B$1 -> 287.29866 | D26: =D25/$B$1 -> 377.33691 | E26: =E25/$B$1 -> 377.47181 | F26: =F25/$B$1 -> 274.12215 | G26: =SUM(B26:F26) -> 1421.2255 | H26: =H25/$B$1 -> 1409.396 | I26: =I25/$B$1 -> 1470.2333
A27: Leads Ingresados | B27: 9 | C27: 74 | D27: 78 | E27: 86 | F27: 64 | G27: =SUM(B27:F27) -> 311 | H27: =B172 -> 381.81818 | I27: =$G27/$G$1*30 -> 321.72414
A28: CPL | B28: =B25/B27 -> 17382.667 | C28: =C25/C27 -> 5784.7973 | D28: =D25/D27 -> 7208.1026 | E28: =E25/E27 -> 6539.9186 | F28: =F25/F27 -> 6381.9062 | G28: =G25/G$27 -> 6809.0868 | H28: =H25/H27 -> 5500 | I28: =I25/I27 -> 6809.0868
A29: CPL USD | B29: =B28/$B$1 -> 11.666219 | C29: =C28/$B$1 -> 3.8824143 | D29: =D28/$B$1 -> 4.8376527 | E29: =E28/$B$1 -> 4.3892071 | F29: =F28/$B$1 -> 4.2831586 | G29: =G26/G$27 -> 4.5698569 | H29: =H28/$B$1 -> 3.6912752 | I29: =I28/$B$1 -> 4.5698569
A30: Reuniones | B30: 2 | C30: 5 | D30: 5 | E30: 6 | F30: 6 | G30: =SUM(B30:F30) -> 24 | H30: =B174 -> 38.181818 | I30: =$G30/$G$1*30 -> 24.827586
A31: CPR | B31: =B25/B30 -> 78222 | C31: =C25/C30 -> 85615 | D31: =D25/D30 -> 112446.4 | E31: =E25/E30 -> 93738.833 | F31: =F25/F30 -> 68073.667 | G31: =G25/G$30 -> 88234.417 | H31: =H25/H30 -> 55000 | I31: =I25/I30 -> 88234.417
A32: CPR USD | B32: =B31/$B$1 -> 52.497987 | C32: =C31/$B$1 -> 57.459732 | D32: =D31/$B$1 -> 75.467383 | E32: =E31/$B$1 -> 62.911969 | F32: =F31/$B$1 -> 45.687025 | G32: =G26/G$30 -> 59.217729 | H32: =H31/$B$1 -> 36.912752 | I32: =I31/$B$1 -> 59.217729
A33: % Lead a reunión | B33: =B30/B27 -> 0.22222222 | C33: =C30/C27 -> 0.067567568 | D33: =D30/D27 -> 0.064102564 | E33: =E30/E27 -> 0.069767442 | F33: =F30/F27 -> 0.09375 | G33: =G30/G27 -> 0.077170418 | H33: =H30/H27 -> 0.1 | I33: =I30/I27 -> 0.077170418
A34: Cierres | C34: 0 | G34: =SUM(B34:D34) -> 0 | I34: =$G34/$G$1*30 -> 0
A35: CP_CIERRE | I35: =I25/I34 -> #DIV/0!
A36: CPC USD | B36: =B35/$B$1 -> 0 | C36: =C35/$B$1 -> 0 | D36: =D35/$B$1 -> 0
A37: % lead a cierre | I37: =I34/I27 -> 0
A40: DISTRIBUIDORA
A41: Métrica / fecha | B41: =B3 -> 01/12 al 02/12 | C41: =C3 -> 03/12 al 09/12 | D41: =D3 -> 10/12 al 16/12 | E41: =E3 -> 17/12 al 23/12 | F41: =F3 -> 24/12 al 31/12 | G41: TOTAL | H41: OBJETIVO | I41: PROYECC
A42: Inversión total | B42: =103124+109332 -> 212456 | C42: =418678+10140 -> 428818 | D42: =113255+33529+419175 -> 565959 | E42: =113291+33529+419340 -> 566160 | F42: =115963+348453 -> 464416 | G42: =SUM(B42:F42) -> 2237809 | H42: =C169 -> 2100000 | I42: =$G42/$G$1*30 -> 2314974.8 | J42: =(H42-G42)/15 -> -9187.2667
A43: Inv USD | B43: =B42/$B$1 -> 142.58792 | C43: =C42/$B$1 -> 287.79732 | D43: =D42/$B$1 -> 379.83826 | E43: =E42/$B$1 -> 379.97315 | F43: =F42/$B$1 -> 311.68859 | G43: =SUM(B43:F43) -> 1501.8852 | H43: =H42/$B$1 -> 1409.396
...

Sheet Noviembre_25
A1: TC | B1: 1490 | F1: DIA | G1: 30 | H1: % DEL MES | I1: =G1/30 -> 1
A2: TOTALES
A3: Métrica / fecha | B3: 01/11 al 04/11 | C3: 05/11 al 11/11 | D3: 12/11 al 18/11 | E3: 19/11 al 25/11 | F3: 26/11 al 30/11 | G3: TOTAL | H3: OBJETIVO | I3: % DE LOGRO | J3: PROYECC | K3: En líneas generales, el costo por lead disminuyó durante la segunda semana del mes y también aumentó la cantidad de reuniones efectivas. Sin embargo, los números muestran que aún debemos optimizar la calidad de los leads, especialmente en el segmento de distribuidores. En este caso, el costo por lead se incrementó y, en comparación, la cantidad de reuniones efectivas fue baja, lo que indica que necesitamos seguir mejorando la segmentación y la calidad del público. Por este motivo, volveremos a subir una base de datos actualizada para crear públicos similares, priorizando a las personas que ya concretaron reuniones, con el objetivo de obtener leads de mayor calidad. Además, vamos a analizar si en Kommo es posible identificar los días específicos en los que se reciben más mensajes. Si es así, programaremos en Meta Ads un aumento de inversión en esos días puntuales para potenciar la cantidad de contactos generados.
A4: Inversión total | B4: 1178176 | C4: 1778840 | D4: 1614500 | E4: 1329127 | F4: 1474508 | G4: =SUM(B4:F4) -> 7375151 | H4: 8550000 | I4: =G4/H4 -> 0.86259076 | J4: =$G4/$G$1*30 -> 7375151
A5: Inv USD | B5: =B4/$B$1 -> 790.72215 | C5: =C4/$B$1 -> 1193.8523 | D5: =D4/$B$1 -> 1083.557 | E5: =E4/$B$1 -> 892.03154 | F5: =F4/$B$1 -> 989.60268 | G5: =SUM(B5:F5) -> 4949.7658 | H5: =H4/$B$1 -> 5738.255 | I5: =G5/H5 -> 0.86259076 | J5: =J4/$B$1 -> 4949.7658
A6: Leads Ingresados | B6: 186 | C6: 618 | D6: 705 | E6: 196 | F6: 558 | G6: =SUM(B6:F6) -> 2263 | H6: 1632 | I6: =G6/H6 -> 1.3866422 | J6: =$G6/$G$1*30 -> 2263
A7: CPL | B7: =B4/B6 -> 6334.2796 | C7: =C4/C6 -> 2878.3819 | D7: =D4/D6 -> 2290.0709 | E7: =E4/E6 -> 6781.2602 | F7: =F4/F6 -> 2642.4875 | G7: =G4/$G$6 -> 3259.015 | H7: =H4/H6 -> 5238.9706 | I7: =H7/G7-1 -> 0.60753189 | J7: =J4/J6 -> 3259.015
A8: CPL USD | B8: =B7/$B$1 -> 4.2511943 | C8: =C7/$B$1 -> 1.9317999 | D8: =D7/$B$1 -> 1.5369603 | E8: =E7/$B$1 -> 4.5511813 | F8: =F7/$B$1 -> 1.7734815 | G8: =G5/G$6 -> 2.1872584 | H8: =H5/H$6 -> 3.5160876
A9: Reuniones agendadas | B9: 17 | C9: 51 | D9: 38 | E9: 12 | F9: 14 | G9: =SUM(B9:F9) -> 132 | H9: 157 | I9: =G9/H9 -> 0.84076433 | J9: =$G9/$G$1*30 -> 132
A10: Reuniones efectivas | B10: 16 | C10: 44 | D10: 19 | E10: 11 | F10: 8 | G10: =SUM(B10:F10) -> 98
A11: CPR | B11: =B4/B9 -> 69304.471 | C11: =C4/C9 -> 34879.216 | D11: =D4/D9 -> 42486.842 | E11: =E4/E9 -> 110760.58 | F11: =F4/F9 -> 105322 | G11: =G4/G$9 -> 55872.356 | H11: =H4/H9 -> 54458.599 | J11: =J4/J9 -> 55872.356
A12: CPR USD | B12: =B11/$B$1 -> 46.513068 | C12: =C11/$B$1 -> 23.40887 | D12: =D11/$B$1 -> 28.514659 | E12: =E11/$B$1 -> 74.335962 | F12: =F11/$B$1 -> 70.685906 | G12: =G5/G$9 -> 37.498226 | H12: =H5/H$9 -> 36.549395
A13: % Lead a reunión | B13: =B9/B6 -> 0.091397849 | C13: =C9/C6 -> 0.082524272 | D13: =D9/D6 -> 0.053900709 | E13: =E9/E6 -> 0.06122449 | F13: =F9/F6 -> 0.025089606 | G13: =G9/G6 -> 0.058329651 | H13: =H9/H6 -> 0.09620098 | J13: =J9/J6 -> 0.058329651
A14: Embudo | B14: 1 | C14: 4 | D14: 3 | E14: 2 | F14: 1 | G14: =SUM(B14:F14) -> 11
A15: CPE | B15: =B4/B14 -> 1178176 | C15: =C4/C14 -> 444710 | D15: =D4/D14 -> 538166.67 | E15: =E4/E14 -> 664563.5 | F15: =F4/F14 -> 1474508 | G15: =G4/G14 -> 670468.27
A16: CPE USD | B16: =B15/$B$1 -> 790.72215 | C16: =C15/$B$1 -> 298.46309 | D16: =D15/$B$1 -> 361.18568 | E16: =E15/$B$1 -> 446.01577 | F16: =F15/$B$1 -> 989.60268 | G16: =G15/$B$1 -> 449.97871
A17: % Lead a embudo | B17: =B14/B6 -> 0.0053763441 | C17: =C14/C6 -> 0.0064724919 | D17: =D14/D6 -> 0.0042553191 | E17: =E14/E6 -> 0.010204082 | F17: =F14/F6 -> 0.0017921147 | G17: =G14/G6 -> 0.0048608042
A18: Cierres | G18: =SUM(B18:F18) -> 0 | J18: =$G18/$G$1*30 -> 0
A19: Costo por Cierre | B19: =B5/B18 -> #DIV/0! | C19: =C4/C18 -> #DIV/0! | D19: =D4/D18 -> #DIV/0! | E19: =E4/E18 -> #DIV/0! | F19: =F4/F18 -> #DIV/0! | G19: =G4/G$18 -> #DIV/0! | J19: =J4/J18 -> #DIV/0!
A20: CPC USD | B20: =B19/$B$1 -> #DIV/0! | C20: =C19/$B$1 -> #DIV/0! | D20: =D19/$B$1 -> #DIV/0! | E20: =E19/$B$1 -> #DIV/0! | F20: =F19/$B$1 -> #DIV/0! | G20: =G5/G$18 -> #DIV/0!
A21: % lead a cierre | B21: =B18/B6 -> 0 | C21: =C18/C6 -> 0 | D21: =D18/D6 -> 0 | E21: =E18/E6 -> 0 | F21: =F18/F6 -> 0 | G21: =G18/G6 -> 0 | J21: =J18/J6 -> 0
A23: CORRALONES
A24: Métrica / fecha | B24: =B3 -> 01/11 al 04/11 | C24: =C3 -> 05/11 al 11/11 | D24: =D3 -> 12/11 al 18/11 | E24: =E3 -> 19/11 al 25/11 | F24: =F3 -> 26/11 al 30/11 | G24: TOTAL | H24: OBJETIVO | I24: PROYECC
A25: Inversión total | B25: 247566 | C25: 419701 | D25: 415519 | E25: 282777 | F25: =252254+53672 -> 305926 | G25: =SUM(B25:F25) -> 1671489 | H25: =B169 -> 1800000 | I25: =$G25/$G$1*30 -> 1671489 | J25: =(H25-G25)/15 -> 8567.4
A26: Inv USD | B26: =B25/$B$1 -> 166.15168 | C26: =C25/$B$1 -> 281.67852 | D26: =D25/$B$1 -> 278.87181 | E26: =E25/$B$1 -> 189.78322 | F26: =F25/$B$1 -> 205.31946 | G26: =SUM(B26:F26) -> 1121.8047 | H26: =H25/$B$1 -> 1208.0537 | I26: =I25/$B$1 -> 1121.8047
A27: Leads Ingresados | B27: 24 | C27: 52 | D27: 56 | E27: 19 | F27: 43 | G27: =SUM(B27:F27) -> 194 | H27: =B172 -> 257.14286 | I27: =$G27/$G$1*30 -> 194
A28: CPL | B28: =B25/B27 -> 10315.25 | C28: =C25/C27 -> 8071.1731 | D28: =D25/D27 -> 7419.9821 | E28: =E25/E27 -> 14883 | F28: =F25/F27 -> 7114.5581 | G28: =G25/G$27 -> 8615.9227 | H28: =H25/H27 -> 7000 | I28: =I25/I27 -> 8615.9227
A29: CPL USD | B29: =B28/$B$1 -> 6.9229866 | C29: =C28/$B$1 -> 5.4168947 | D29: =D28/$B$1 -> 4.9798538 | E29: =E28/$B$1 -> 9.9885906 | F29: =F28/$B$1 -> 4.7748712 | G29: =G26/G$27 -> 5.7824984 | H29: =H28/$B$1 -> 4.6979866 | I29: =I28/$B$1 -> 5.7824984
A30: Reuniones | B30: 5 | C30: 7 | D30: 3 | E30: 1 | F30: 1 | G30: =SUM(B30:F30) -> 17 | H30: =B174 -> 33.428571 | I30: =$G30/$G$1*30 -> 17
A31: CPR | B31: =B25/B30 -> 49513.2 | C31: =C25/C30 -> 59957.286 | D31: =D25/D30 -> 138506.33 | E31: =E25/E30 -> 282777 | F31: =F25/F30 -> 305926 | G31: =G25/G$30 -> 98322.882 | H31: =H25/H30 -> 53846.154 | I31: =I25/I30 -> 98322.882
A32: CPR USD | B32: =B31/$B$1 -> 33.230336 | C32: =C31/$B$1 -> 40.239789 | D32: =D31/$B$1 -> 92.957271 | E32: =E31/$B$1 -> 189.78322 | F32: =F31/$B$1 -> 205.31946 | G32: =G26/G$30 -> 65.988512 | H32: =H31/$B$1 -> 36.138358 | I32: =I31/$B$1 -> 65.988512
A33: % Lead a reunión | B33: =B30/B27 -> 0.20833333 | C33: =C30/C27 -> 0.13461538 | D33: =D30/D27 -> 0.053571429 | E33: =E30/E27 -> 0.052631579 | F33: =F30/F27 -> 0.023255814 | G33: =G30/G27 -> 0.087628866 | H33: =H30/H27 -> 0.13 | I33: =I30/I27 -> 0.087628866
A34: Cierres | G34: =SUM(B34:D34) -> 0 | I34: =$G34/$G$1*30 -> 0
A35: CP_CIERRE | I35: =I25/I34 -> #DIV/0!
A36: CPC USD | B36: =B35/$B$1 -> 0 | C36: =C35/$B$1 -> 0 | D36: =D35/$B$1 -> 0
A37: % lead a cierre | I37: =I34/I27 -> 0
A40: DISTRIBUIDORA
A41: Métrica / fecha | B41: =B3 -> 01/11 al 04/11 | C41: =C3 -> 05/11 al 11/11 | D41: =D3 -> 12/11 al 18/11 | E41: =E3 -> 19/11 al 25/11 | F41: =F3 -> 26/11 al 30/11 | G41: TOTAL | H41: OBJETIVO | I41: PROYECC
A42: Inversión total | B42: =63791+122412+25379 -> 211582 | C42: =103107+197958+2545 -> 303610 | D42: =107344+197252 -> 304596 | E42: =131397+65860 -> 197257 | F42: =16993+316298 -> 333291 | G42: =SUM(B42:F42) -> 1350336 | H42: =C169 -> 1200000 | I42: =$G42/$G$1*30 -> 1350336 | J42: =(H42-G42)/15 -> -10022.4
A43: Inv USD | B43: =B42/$B$1 -> 142.00134 | C43: =C42/$B$1 -> 203.7651 | D43: =D42/$B$1 -> 204.42685 | E43: =E42/$B$1 -> 132.38725 | F43: =F42/$B$1 -> 223.68523 | G43: =SUM(B43:F43) -> 906.26577 | H43: =H42/$B$1 -> 805.36913
...

Sheet Octubre_25
A1: TC | B1: 1490 | F1: DIA | G1: 30 | H1: % DEL MES | I1: =G1/30 -> 1
A2: TOTALES
A3: Métrica / fecha | B3: 01/10 al 07/10 | C3: 08/10 al 14/10 | D3: 15/10 al 21/10 | E3: 22/10 al 28/10 | F3: 29/10 al 31/10 | G3: TOTAL | H3: OBJETIVO | I3: % DE LOGRO | J3: PROYECC | K3: Resumen de resultados: Observamos que el costo por lead ha bajado, probablemente gracias a la base de datos que subimos para mejorar la calidad de los contactos. Propuestas de mejora: • Trabajar sobre los creativos de los anuncios para realizar testeos constantes. • Producir un video más profesional que muestre las funcionalidades del software de InfoManager, transmitiendo mayor calidad y destacando el valor agregado frente a la competencia. Ejemplo • Comunicar en los anuncios el diferencial de InfoManager a comparación de la competencia como eje principal. • Realizar testeos mensuales de diferentes formatos (videos, carruseles y piezas estáticas) para optimizar el rendimiento de las campañas. • Renovar mensualmente la base de datos para ampliar las posibilidades de captar leads de calidad.
A4: Inversión total | B4: =1864968+168000 -> 2032968 | C4: =+149000+1821978 -> 1970978 | D4: 1964726 | E4: 1827437 | F4: 874435 | G4: =SUM(B4:F4) -> 8670544 | H4: 8550000 | I4: =G4/H4 -> 1.0140987 | J4: =$G4/$G$1*30 -> 8670544
A5: Inv USD | B5: =B4/$B$1 -> 1364.4081 | C5: =C4/$B$1 -> 1322.804 | D5: =D4/$B$1 -> 1318.6081 | E5: =E4/$B$1 -> 1226.4678 | F5: =F4/$B$1 -> 586.86913 | G5: =SUM(B5:F5) -> 5819.157 | H5: =H4/$B$1 -> 5738.255 | I5: =G5/H5 -> 1.0140987 | J5: =J4/$B$1 -> 5819.157
A6: Leads Ingresados | B6: 453 | C6: 466 | D6: 384 | E6: 385 | F6: 111 | G6: =SUM(B6:F6) -> 1799 | H6: =H4/H7 -> 1811.4407 | I6: =G6/H6 -> 0.99313216 | J6: =$G6/$G$1*30 -> 1799
A7: CPL | B7: =B4/B6 -> 4487.7881 | C7: =C4/C6 -> 4229.5665 | D7: =D4/D6 -> 5116.474 | E7: =E4/E6 -> 4746.5896 | F7: =F4/F6 -> 7877.7928 | G7: =G4/$G$6 -> 4819.6465 | H7: 4720 | I7: =H7/G7-1 -> -0.020675058 | J7: =J4/J6 -> 4819.6465
A8: CPL USD | B8: =B7/$B$1 -> 3.0119383 | C8: =C7/$B$1 -> 2.8386353 | D8: =D7/$B$1 -> 3.4338751 | E8: =E7/$B$1 -> 3.1856306 | F8: =F7/$B$1 -> 5.2871093 | G8: =G5/G$6 -> 3.2346621 | H8: =H5/H$6 -> 3.1677852
A9: Reuniones agendadas | B9: 31 | C9: 31 | D9: 38 | E9: 42 | F9: 18 | G9: =SUM(B9:F9) -> 160 | H9: =H6*H13 -> 166.4714 | I9: =G9/H9 -> 0.96112607 | J9: =$G9/$G$1*30 -> 160
A10: Reuniones efectivas | B10: 31 | C10: 31 | D10: 38 | E10: 39 | F10: 11 | G10: =SUM(B10:F10) -> 150
A11: CPR | B11: =B4/B9 -> 65579.613 | C11: =C4/C9 -> 63579.935 | D11: =D4/D9 -> 51703.316 | E11: =E4/E9 -> 43510.405 | F11: =F4/F9 -> 48579.722 | G11: =G4/G$9 -> 54190.9 | H11: =H4/H9 -> 51360.174 | J11: =J4/J9 -> 54190.9
A12: CPR USD | B12: =B11/$B$1 -> 44.013163 | C12: =C11/$B$1 -> 42.671098 | D12: =D11/$B$1 -> 34.700212 | E12: =E11/$B$1 -> 29.201614 | F12: =F11/$B$1 -> 32.60384 | G12: =G5/G$9 -> 36.369732 | H12: =H5/H$9 -> 34.469915
A13: % Lead a reunión | B13: =B9/B6 -> 0.068432671 | C13: =C9/C6 -> 0.066523605 | D13: =D9/D6 -> 0.098958333 | E13: =E9/E6 -> 0.10909091 | F13: =F9/F6 -> 0.16216216 | G13: =G9/G6 -> 0.088938299 | H13: 0.0919 | J13: =J9/J6 -> 0.088938299
A14: Embudo | B14: 4 | C14: 3 | D14: 6 | E14: 3 | G14: =SUM(B14:F14) -> 16
A15: CPE | B15: =B4/B14 -> 508242 | C15: =C4/C14 -> 656992.67 | D15: =D4/D14 -> 327454.33 | E15: =E4/E14 -> 609145.67 | G15: =G4/G14 -> 541909
A16: CPE USD | B16: =B15/$B$1 -> 341.10201 | C16: =C15/$B$1 -> 440.93468 | D16: =D15/$B$1 -> 219.76801 | E16: =E15/$B$1 -> 408.8226 | G16: =G15/$B$1 -> 363.69732
A17: % Lead a embudo | B17: =B14/B6 -> 0.0088300221 | C17: =C14/C6 -> 0.0064377682 | D17: =D14/D6 -> 0.015625 | E17: =E14/E6 -> 0.0077922078 | G17: =G14/G6 -> 0.0088938299
A18: Cierres | C18: 0.8 | D18: 3.5 | E18: 1 | G18: =SUM(B18:F18) -> 5.3 | J18: =$G18/$G$1*30 -> 5.3
A19: Costo por Cierre | B19: =B5/B18 -> #DIV/0! | C19: =C4/C18 -> 2463722.5 | D19: =D4/D18 -> 561350.29 | E19: =E4/E18 -> 1827437 | F19: =F4/F18 -> #DIV/0! | G19: =G4/G$18 -> 1635951.7 | J19: =J4/J18 -> 1635951.7
A20: CPC USD | B20: =B19/$B$1 -> #DIV/0! | C20: =C19/$B$1 -> 1653.505 | D20: =D19/$B$1 -> 376.74516 | E20: =E19/$B$1 -> 1226.4678 | F20: =F19/$B$1 -> #DIV/0! | G20: =G5/G$18 -> 1097.9542
A21: % lead a cierre | B21: =B18/B6 -> 0 | C21: =C18/C6 -> 0.0017167382 | D21: =D18/D6 -> 0.0091145833 | E21: =E18/E6 -> 0.0025974026 | F21: =F18/F6 -> 0 | G21: =G18/G6 -> 0.0029460812 | J21: =J18/J6 -> 0.0029460812
A23: CORRALONES
A24: Métrica / fecha | B24: =B3 -> 01/10 al 07/10 | C24: =C3 -> 08/10 al 14/10 | D24: =D3 -> 15/10 al 21/10 | E24: =E3 -> 22/10 al 28/10 | F24: =F3 -> 29/10 al 31/10 | G24: TOTAL | H24: OBJETIVO | I24: PROYECC | K24: Resumen de resultados: En cuanto a la cantidad de leads, este mes ingresaron más que el mes pasado: en el mes anterior se obtuvieron 156 leads, mientras que este mes llevamos 232. Sin embargo, a pesar del aumento en cantidad, sería necesario mejorar la calidad de los leads, ya que el costo de la cuarta semana fue elevado. Propuestas de mejora: • Optimizar la calidad de los anuncios para mejorar la conversión de leads. • Tomar como referencia el video de Gaby, que tuvo buen rendimiento, y desarrollar una nueva pieza similar. • Incorporar carruseles a la estrategia, ya que hasta el momento solo se han utilizado formatos de video y piezas estáticas. • Continuar utilizando la base de datos actualizada para seguir mejorando la segmentación y la calidad de los leads.
A25: Inversión total | B25: 380186 | C25: 415748 | D25: 415168 | E25: 402382 | F25: 187069 | G25: =SUM(B25:F25) -> 1800553 | H25: =B169 -> 1650000 | I25: =$G25/$G$1*30 -> 1800553 | J25: =(H25-G25)/15 -> -10036.867
A26: Inv USD | B26: =B25/$B$1 -> 255.15839 | C26: =C25/$B$1 -> 279.0255 | D26: =D25/$B$1 -> 278.63624 | E26: =E25/$B$1 -> 270.05503 | F26: =F25/$B$1 -> 125.54966 | G26: =SUM(B26:F26) -> 1208.4248 | H26: =H25/$B$1 -> 1107.3826 | I26: =I25/$B$1 -> 1208.4248
A27: Leads Ingresados | B27: 63 | C27: 56 | D27: 50 | E27: 63 | F27: 25 | G27: =SUM(B27:F27) -> 257 | H27: =B172 -> 220 | I27: =$G27/$G$1*30 -> 257
A28: CPL | B28: =B25/B27 -> 6034.6984 | C28: =C25/C27 -> 7424.0714 | D28: =D25/D27 -> 8303.36 | E28: =E25/E27 -> 6387.0159 | F28: =F25/F27 -> 7482.76 | G28: =G25/G$27 -> 7006.0428 | H28: =H25/H27 -> 7500 | I28: =I25/I27 -> 7006.0428
A29: CPL USD | B29: =B28/$B$1 -> 4.0501332 | C29: =C28/$B$1 -> 4.9825983 | D29: =D28/$B$1 -> 5.5727248 | E29: =E28/$B$1 -> 4.2865878 | F29: =F28/$B$1 -> 5.0219866 | G29: =G26/G$27 -> 4.7020421 | H29: =H28/$B$1 -> 5.033557 | I29: =I28/$B$1 -> 4.7020421
A30: Reuniones | B30: 8 | C30: 8 | D30: 10 | E30: 4 | F30: 4 | G30: =SUM(B30:F30) -> 34 | H30: =B174 -> 26.4 | I30: =$G30/$G$1*30 -> 34
A31: CPR | B31: =B25/B30 -> 47523.25 | C31: =C25/C30 -> 51968.5 | D31: =D25/D30 -> 41516.8 | E31: =E25/E30 -> 100595.5 | F31: =F25/F30 -> 46767.25 | G31: =G25/G$30 -> 52957.441 | H31: =H25/H30 -> 62500 | I31: =I25/I30 -> 52957.441
A32: CPR USD | B32: =B31/$B$1 -> 31.894799 | C32: =C31/$B$1 -> 34.878188 | D32: =D31/$B$1 -> 27.863624 | E32: =E31/$B$1 -> 67.513758 | F32: =F31/$B$1 -> 31.387416 | G32: =G26/G$30 -> 35.541907 | H32: =H31/$B$1 -> 41.946309 | I32: =I31/$B$1 -> 35.541907
A33: % Lead a reunión | B33: =B30/B27 -> 0.12698413 | C33: =C30/C27 -> 0.14285714 | D33: =D30/D27 -> 0.2 | E33: =E30/E27 -> 0.063492063 | F33: =F30/F27 -> 0.16 | G33: =G30/G27 -> 0.13229572 | H33: =H30/H27 -> 0.12 | I33: =I30/I27 -> 0.13229572
A34: Cierres | G34: =SUM(B34:D34) -> 0 | I34: =$G34/$G$1*30 -> 0
A35: CP_CIERRE | I35: =I25/I34 -> #DIV/0!
A36: CPC USD | B36: =B35/$B$1 -> 0 | C36: =C35/$B$1 -> 0 | D36: =D35/$B$1 -> 0
A37: % lead a cierre | I37: =I34/I27 -> 0
A40: DISTRIBUIDORA
A41: Métrica / fecha | B41: =B3 -> 01/10 al 07/10 | C41: =C3 -> 08/10 al 14/10 | D41: =D3 -> 15/10 al 21/10 | E41: =E3 -> 22/10 al 28/10 | F41: =F3 -> 29/10 al 31/10 | G41: TOTAL | H41: OBJETIVO | I41: PROYECC | K41: Vemos que durante la tercera y cuarta semana los costos por lead mejoraron. Justamente en la tercera semana se subió la base de datos, y es probable que ese cambio haya contribuido a generar más reuniones. Además, se pausaron los anuncios que no estaban funcionando para optimizar el presupuesto y reducir costos.
A42: Inversión total | B42: 356668 | C42: 359096 | D42: =209229+42698+104466 -> 356393 | E42: =99134+200977+40420 -> 340531 | F42: =46949+94100+17423 -> 158472 | G42: =SUM(B42:F42) -> 1571160 | H42: =C169 -> 1500000 | I42: =$G42/$G$1*30 -> 1571160 | J42: =(H42-G42)/15 -> -4744
A43: Inv USD | B43: =B42/$B$1 -> 239.3745 | C43: =C42/$B$1 -> 241.00403 | D43: =D42/$B$1 -> 239.18993 | E43: =E42/$B$1 -> 228.5443 | F43: =F42/$B$1 -> 106.35705 | G43: =SUM(B43:F43) -> 1054.4698 | H43: =H42/$B$1 -> 1006.7114
...

Sheet Septiembre_25
A1: TC | B1: 1381 | F1: DIA | G1: 30 | H1: % DEL MES | I1: =G1/30 -> 1
A2: TOTALES
A3: Métrica / fecha | B3: 01/09 al 07/09 | C3: 08/09 al 14/09 | D3: 15/09 al 21/09 | E3: 22/09 al 28/09 | F3: 29/09 al 30/09 | G3: TOTAL | H3: OBJETIVO | I3: % DE LOGRO | J3: PROYECC | K3: LECTURAS SEMANA 1 Durante la primer semana de Septiembre el CPL fué de $4.375, por encima del objetivo de $4.000. A nivel general, la tasa de Lead a Reunión fué de 11,39%, superando el 8% esperado. El rubro con mejor rendimiento fué Carnicerías, que logró el mayor volumen de leads, con un CPL eficiente y una tasa de Lead a Reunión del 12,17%, por encima del objetivo. Se destaca el canal web, que a pesar de tener un bajo volumen de leads tienen una muy buena calidad, generando un 12% de tasa de Lead a Reunión. Distribuidras fué el rubro más débil, con un CPL elevado de $9.352 y baja tasa de Lead a Turno 3,7%.
A4: Inversión total | B4: =1297798+85000 -> 1382798 | C4: =150000+1507773 -> 1657773 | D4: =107000+1706941 -> 1813941 | E4: =216000+1735414 -> 1951414 | F4: =536169+27700 -> 563869 | G4: =SUM(B4:F4) -> 7369795 | H4: 8550000 | I4: =G4/H4 -> 0.86196433 | J4: =$G4/$G$1*30 -> 7369795
A5: Inv USD | B5: =B4/$B$1 -> 1001.302 | C5: =C4/$B$1 -> 1200.4149 | D5: =D4/$B$1 -> 1313.4982 | E5: =E4/$B$1 -> 1413.0442 | F5: =F4/$B$1 -> 408.30485 | G5: =SUM(B5:F5) -> 5336.5641 | H5: =H4/$B$1 -> 6191.1658 | I5: =G5/H5 -> 0.86196433 | J5: =J4/$B$1 -> 5336.5641
A6: Leads Ingresados | B6: 316 | C6: 369 | D6: 358 | E6: 411 | F6: 119 | G6: =SUM(B6:F6) -> 1573 | H6: =H4/H7 -> 1905.0802 | I6: =G6/H6 -> 0.82568702 | J6: =$G6/$G$1*30 -> 1573
A7: CPL | B7: =B4/B6 -> 4375.943 | C7: =C4/C6 -> 4492.6098 | D7: =D4/D6 -> 5066.8743 | E7: =E4/E6 -> 4747.9659 | F7: =F4/F6 -> 4738.395 | G7: =G4/$G$6 -> 4685.1844 | H7: 4488 | I7: =H7/G7-1 -> -0.042086788 | J7: =J4/J6 -> 4685.1844
A8: CPL USD | B8: =B7/$B$1 -> 3.1686771 | C8: =C7/$B$1 -> 3.253157 | D8: =D7/$B$1 -> 3.6689894 | E8: =E7/$B$1 -> 3.4380637 | F8: =F7/$B$1 -> 3.4311332 | G8: =G5/G$6 -> 3.3926027 | H8: =H5/H$6 -> 3.249819
A9: Reuniones Agendadas | B9: 39 | C9: 39 | D9: 39 | E9: 32 | F9: 13 | G9: =SUM(B9:F9) -> 162 | H9: =H6*H13 -> 161.93182 | I9: =G9/H9 -> 1.0004211 | J9: =$G9/$G$1*30 -> 162
A10: Reuniones Efectivas | B10: 37 | C10: 37 | D10: 38 | E10: 23 | F10: 8 | G10: =SUM(B10:F10) -> 143 | H10: 162
A11: CPR | B11: =B4/B10 -> 37372.919 | C11: =C4/C10 -> 44804.676 | D11: =D4/D10 -> 47735.289 | E11: =E4/E10 -> 84844.087 | F11: =F4/F10 -> 70483.625 | G11: =G4/G$10 -> 51537.028 | H11: =H4/H10 -> 52777.778 | J11: =J4/J9 -> 45492.562
A12: CPR USD | B12: =B11/$B$1 -> 27.062215 | C12: =C11/$B$1 -> 32.443646 | D12: =D11/$B$1 -> 34.565742 | E12: =E11/$B$1 -> 61.436703 | F12: =F11/$B$1 -> 51.038106 | G12: =G5/G$10 -> 37.31863 | H12: =H5/H$9 -> 38.233164
A13: % Lead a reunión | B13: =B9/B6 -> 0.12341772 | C13: =C9/C6 -> 0.10569106 | D13: =D9/D6 -> 0.10893855 | E13: =E9/E6 -> 0.077858881 | F13: =F9/F6 -> 0.1092437 | G13: =G9/G6 -> 0.10298792 | H13: 0.085 | J13: =J9/J6 -> 0.10298792
A14: Cierres | B14: 1 | C14: 1 | D14: 1 | E14: 1 | F14: 1 | G14: =SUM(B14:F14) -> 5 | J14: =$G14/$G$1*30 -> 5
A15: Costo por Cierre | B15: =B4/B14 -> 1382798 | C15: =C4/C14 -> 1657773 | D15: =D4/D14 -> 1813941 | E15: =E4/E14 -> 1951414 | F15: =F4/F14 -> 563869 | G15: =G4/G$14 -> 1473959 | J15: =J4/J14 -> 1473959
A16: CPC USD | B16: =B15/$B$1 -> 1001.302 | C16: =C15/$B$1 -> 1200.4149 | D16: =D15/$B$1 -> 1313.4982 | E16: =E15/$B$1 -> 1413.0442 | F16: =F15/$B$1 -> 408.30485 | G16: =G5/G$14 -> 1067.3128
A17: % lead a cierre | B17: =B14/B6 -> 0.003164557 | C17: =C14/C6 -> 0.0027100271 | D17: =D14/D6 -> 0.0027932961 | E17: =E14/E6 -> 0.00243309 | F17: =F14/F6 -> 0.0084033613 | G17: =G14/G6 -> 0.0031786395 | J17: =J14/J6 -> 0.0031786395
A19: CORRALONES
A20: Métrica / fecha | B20: 01/09 al 07/09 | C20: 08/09 al 14/09 | D20: 15/09 al 21/09 | E20: 22/09 al 28/09 | F20: =F3 -> 29/09 al 30/09 | G20: TOTAL | H20: OBJETIVO | I20: PROYECC | K20: LECTURAS SEMANA 2 Durante la segunda semana de Septiembre el CPL fue de $4.086, alineado al objetivo de $4.000 y mejorando respecto a la semana anterior. La tasa de Lead a Reunión se mantuvo en 10,84%, superando el 8% esperado. El rubro con mejor rendimiento fué Fiambrerías, que alcanzó un CPL muy eficiente de $2.107 y una tasa de Lead a Reunión del 14,29%, la más alta del período. Carnicerías también se destacó con el mayor volumen de leads y una tasa de Lead a Reunión de 10,69%, aunque con un CPL algo más elevado que la semana 1. El canal web volvió a mostrar buena calidad, con un CPL de $4.027 y una tasa de Lead a Reunión de 8,11%. El rubro más débil fué Corralones, con un CPL alto de $13.328 y baja tasa de Lead a Reunión del 4,76%
A21: Inversión total | B21: 203672 | C21: 279899 | D21: 373845 | E21: 331528 | F21: 98411 | G21: =SUM(B21:F21) -> 1287355 | H21: 1650000 | I21: =$G21/$G$1*30 -> 1287355 | J21: =(H21-G21)/15 -> 24176.333
A22: Inv USD | B22: =B21/$B$1 -> 147.48154 | C22: =C21/$B$1 -> 202.67849 | D22: =D21/$B$1 -> 270.70601 | E22: =E21/$B$1 -> 240.06372 | F22: =F21/$B$1 -> 71.260681 | G22: =SUM(B22:F22) -> 932.19044
A23: Leads Ingresados | B23: 30 | C23: 21 | D23: 45 | E23: 43 | F23: 17 | G23: =SUM(B23:F23) -> 156 | H23: 330 | I23: =$G23/$G$1*30 -> 156
A24: CPL | B24: =B21/B23 -> 6789.0667 | C24: =C21/C23 -> 13328.524 | D24: =D21/D23 -> 8307.6667 | E24: =E21/E23 -> 7709.9535 | F24: =F21/F23 -> 5788.8824 | G24: =G21/G$23 -> 8252.2756 | H24: =H21/H23 -> 5000 | I24: =I21/I23 -> 8252.2756
A25: CPL USD | B25: =B24/$B$1 -> 4.9160512 | C25: =C24/$B$1 -> 9.6513569 | D25: =D24/$B$1 -> 6.0156891 | E25: =E24/$B$1 -> 5.5828773 | F25: =F24/$B$1 -> 4.1918047 | G25: =G22/G$23 -> 5.9755798
A26: Reuniones agendadas | B26: 3 | C26: 1 | D26: 11 | E26: 7 | F26: 7 | G26: =SUM(B26:F26) -> 29 | H26: 25 | I26: =$G26/$G$1*30 -> 29
A27: Reuniones efectivas | B27: 3 | C27: 1 | D27: 9 | E27: 6 | F27: 6 | G27: =SUM(B27:F27) -> 25
A28: CPR | B28: =B21/B27 -> 67890.667 | C28: =C21/C27 -> 279899 | D28: =D21/D27 -> 41538.333 | E28: =E21/E27 -> 55254.667 | F28: =F21/F27 -> 16401.833 | G28: =G21/G$27 -> 51494.2 | H28: =H21/H26 -> 66000 | I28: =I21/I26 -> 44391.552
A29: CPR USD | B29: =B28/$B$1 -> 49.160512 | C29: =C28/$B$1 -> 202.67849 | D29: =D28/$B$1 -> 30.078446 | E29: =E28/$B$1 -> 40.01062 | F29: =F28/$B$1 -> 11.87678 | G29: =G22/G$27 -> 37.287618
A30: % Lead a reunión | B30: =B27/B23 -> 0.1 | C30: =C27/C23 -> 0.047619048 | D30: =D27/D23 -> 0.2 | E30: =E27/E23 -> 0.13953488 | F30: =F27/F23 -> 0.35294118 | G30: =G27/G23 -> 0.16025641 | H30: =H26/H23 -> 0.075757576 | I30: =I26/I23 -> 0.18589744
A31: Cierres | B31: 0 | C31: 0 | D31: 0 | G31: 1 | I31: =$G31/$G$1*30 -> 1
A32: CP_CIERRE | G32: =G21/G31 -> 1287355 | I32: =I21/I31 -> 1287355
A33: CPC USD | B33: =B32/$B$1 -> 0 | C33: =C32/$B$1 -> 0 | D33: =D32/$B$1 -> 0
A34: % lead a cierre | I34: =I31/I23 -> 0.0064102564
A37: DISTRIBUIDORA
A38: Métrica / fecha | B38: 01/09 al 07/09 | C38: 08/09 al 14/09 | D38: 15/09 al 21/09 | E38: 22/09 al 28/09 | F38: =F3 -> 29/09 al 30/09 | G38: TOTAL | H38: OBJETIVO | I38: PROYECC | K38: LECTURAS SEMANA 3 Durante la tercera semana el CPL subió $5.066, por encima del objetivo de $4.000. La tasa de Lead a Reunión se mantuvo estable en 10,89%, superando nuevamente el 8% esperado. Lo que mejor funciono fué Web, que logró un CPL muy eficiente de $2.625 y una tasa de Lead a Reunión de 10,71%, destacándose como el canal de mayor calidad. Carnicerías aportó el mayor volumen de leads, aunque con un CPL más alto de $5.845 y una tasa de Lead a Reunión de 7,81%, por debajo de semanas anteriores. Fiambrerías tuvieron un rendimiento sólido con un CPL de $4.799 y una tasa de Lead a Reunión de 11,43%. El rubro más débil fue Distribuidoras, con un CPL de $6.242 y baja tasa de Lead a Reunión de 5,45%.
A39: Inversión total | B39: 505273 | C39: 395563 | D39: 343327 | E39: 367855 | F39: 115279 | G39: =SUM(B39:F39) -> 1727297 | H39: 1650000 | I39: =$G39/$G$1*30 -> 1727297 | J39: =(H39-G39)/15 -> -5153.1333
A40: Inv USD | B40: =B39/$B$1 -> 365.87473 | C40: =C39/$B$1 -> 286.4323 | D40: =D39/$B$1 -> 248.60753 | E40: =E39/$B$1 -> 266.36857 | F40: =F39/$B$1 -> 83.475018 | G40: =SUM(B40:F40) -> 1250.7581
A41: Leads Ingresados | B41: 56 | C41: 69 | D41: 55 | E41: 75 | F41: 18 | G41: =SUM(B41:F41) -> 273 | H41: 330 | I41: =$G41/$G$1*30 -> 273
A42: CPL | B42: =B39/B41 -> 9022.7321 | C42: =C39/C41 -> 5732.7971 | D42: =D39/D41 -> 6242.3091 | E42: =E39/E41 -> 4904.7333 | F42: =F39/F41 -> 6404.3889 | G42: =G39/G$41 -> 6327.0952 | H42: =H39/H41 -> 5000 | I42: =I39/I41 -> 6327.0952
A43: CPL USD | B43: =B42/$B$1 -> 6.5334773 | C43: =C42/$B$1 -> 4.1511927 | D43: =D42/$B$1 -> 4.5201369 | E43: =E42/$B$1 -> 3.551581 | F43: =F42/$B$1 -> 4.637501 | G43: =G40/G$41 -> 4.5815317
...

Sheet Agosto_25
A1: TC | B1: 1363 | H1: % DEL MES | I1: =30/30 -> 1
A2: TOTALES
A3: Métrica / fecha | B3: 01/08 al 07/08 | C3: 08/08 al 14/08 | D3: 15/08 al 21/08 | E3: 22/08 al 28/08 | F3: 29/08 al 31/08 | G3: TOTAL | H3: OBJETIVO | I3: % DE LOGRO | K3: LECTURAS SEMANA 1 Durante la primera semana de Agosto el Costo por lead estuvo en $8,991, bastante por encima del objetivo de $4,100. Es importante remarcar que el 5/8 se realizó un cambio total de campañas por el bloqueo del numero, lo cual pudo haber impactado en el incremento de costos, ya que en los primeros días posteriores a una reestructuración las campañas pasan por un período de aprendizaje. El rubro con mejor rendimiento fué Distribuidoras con un 7% de leads a reunión.
A4: Inversión total | B4: =B16+B32+B48+B64+B79+B92+B118 -> 2104095 | C4: =C16+C32+C48+C64+C79+C92+C118 -> 1549574 | D4: =D16+D32+D48+D64+D79+D92+D118 -> 1161165 | E4: =143000+1237306 -> 1380306 | F4: =F16+F32+F48+F64+F79+F92+F118 -> 549829 | G4: =SUM(B4:F4) -> 6744969 | H4: 7500000 | I4: =G4/H4 -> 0.8993292
A5: Leads Ingresados | B5: =B17+B33+B49+B65+B80+B93+B106+B119 -> 242 | C5: =C17+C33+C49+C65+C80+C93+C106+C119 -> 335 | D5: =D17+D33+D49+D65+D80+D93+D106+D119 -> 209 | E5: 269 | F5: 100 | G5: =SUM(B5:F5) -> 1155 | H5: =H4/H6 -> 1829.2683 | I5: =G5/H5 -> 0.6314
A6: CPL | B6: =B4/B5 -> 8694.6074 | C6: =C4/C5 -> 4625.594 | D6: =D4/D5 -> 5555.8134 | E6: =E4/E5 -> 5131.2491 | F6: =F4/F5 -> 5498.29 | G6: =G4/G5 -> 5839.8 | H6: 4100 | I6: =H6/G6-1 -> -0.29792116
A7: Reuniones | B7: =B20+B36+B52+B68+B82+B95+B108+B121 -> 18 | C7: =C20+C36+C52+C68+C82+C95+C108+C121 -> 31 | D7: =D20+D36+D52+D68+D82+D95+D108+D121 -> 26 | E7: 33 | F7: 7 | G7: =SUM(B7:F7) -> 115 | H7: =H5*H9 -> 128.04878 | I7: =G7/H7 -> 0.89809524
A8: CPR | B8: =B4/B7 -> 116894.17 | C8: =C4/C7 -> 49986.258 | D8: =D4/D7 -> 44660.192 | E8: =E4/E7 -> 41827.455 | F8: =F4/F7 -> 78547 | G8: =G4/G7 -> 58651.904 | H8: =H4/H7 -> 58571.429
A9: % Lead a reunión | B9: =B7/B5 -> 0.074380165 | C9: =C7/C5 -> 0.092537313 | D9: =D7/D5 -> 0.12440191 | E9: =E7/E5 -> 0.12267658 | F9: =F7/F5 -> 0.07 | G9: =G7/G5 -> 0.0995671 | H9: 0.07
A10: Cierres | B10: 0 | C10: 0 | D10: 0
A11: Costo por Cierre
A12: % lead a cierre
A14: CORRALONES
A15: Métrica / fecha | B15: 01/08 al 07/08 | C15: 08/08 al 14/08 | D15: 15/08 al 21/08 | E15: 22/08 al 28/08 | F15: 29/08 al 31/08 | G15: TOTAL | H15: OBJETIVO | K15: LECTURAS SEMANA 2 El Costo por lead bajó un 47% respecto a la semana pasada. Aunque todavía se mantiene un 12% por encima del objetivo, la tendencia es positiva: con menor inversión se generaron más leads y se mejoró la eficiencia. En el caso de Web, al estar haciendo campañas que optimizan por reuniones, la tasa de lead a reunión es altísima, el costo por lead bajó un 37% respecto a la semana 1. Carnicería tuvo un muy buen rendimiento logrando una tasa de 9,79% de lead a reunión, la mejor entre los demás rubros.
A16: Inversión total | B16: 463118 | C16: 251918 | D16: 152680 | E16: 167670 | F16: 73108 | G16: =SUM(B16:F16) -> 1108494
A17: Leads Ingresados | B17: =26+6 -> 32 | C17: 23 | D17: 17 | E17: 17 | F17: 6 | G17: =SUM(B17:F17) -> 95
A18: CPL | B18: =B16/B17 -> 14472.438 | C18: =C16/C17 -> 10952.957 | D18: =D16/D17 -> 8981.1765 | E18: =E16/E17 -> 9862.9412 | F18: =F16/F17 -> 12184.667 | G18: =G16/G17 -> 11668.358
A19: CPL USD | G19: =G18/B1 -> 8.5607908
A20: Reuniones | B20: 2 | C20: 1 | D20: 2 | E20: 3 | F20: 0 | G20: =SUM(B20:D20) -> 5
A21: CPR | B21: =B16/B20 -> 231559 | C21: =C16/C20 -> 251918 | D21: =D16/D20 -> 76340 | E21: =E16/E20 -> 55890 | F21: =F16/F20 -> #DIV/0! | G21: =G16/G20 -> 221698.8
A22: CRP USD | G22: =G21/B1 -> 162.65503
A23: % Lead a reunión | B23: =B20/B17 -> 0.0625 | C23: =C20/C17 -> 0.043478261 | D23: =D20/D17 -> 0.11764706 | E23: =E20/E17 -> 0.17647059 | F23: =F20/F17 -> 0 | G23: =G20/G17 -> 0.052631579
A24: Cierres | B24: 0 | C24: 0 | D24: 0 | G24: =SUM(B24:D24) -> 0
A25: CP_CIERRE | G25: =G16/G24 -> #DIV/0!
A26: CPC USD
A27: % lead a cierre
A30: DISTRIBUIDORA
A31: Métrica / fecha | B31: 01/08 al 07/08 | C31: 08/08 al 14/08 | D31: 15/08 al 21/08 | E31: 22/08 al 28/08 | F31: 29/08 al 31/08 | G31: TOTAL | H31: OBJETIVO | K31: LECTURAS SEMANA 3 El Costo por Lead subió a $5.483, un 18% más alto que en la semana 2. Sin embargo, al mismo tiempo el % de leads a reunión aumentó del 9,25% al 12,44%, lo que indica que, aunque se pagó más por cada lead, los que ingresaron fueron de mejor calidad y con mayor probabilidad de concretar reuniones. Dentro de los rubros, Web mantuvo una tasa muy alta con un 60% de leads convertidos en reuniones, mientras que Carnicería sobresalió nuevamente con un 12,94%. El costo por lead bajó un 62% respecto a la semana 1.
A32: Inversión total | B32: 828255 | C32: 664512 | D32: 512688 | E32: 562309 | F32: 236921 | G32: =SUM(B32:F32) -> 2804685
A33: Leads Ingresados | B33: 99 | C33: 122 | D33: 64 | E33: 77 | F33: 24 | G33: =SUM(B33:F33) -> 386
A34: CPL | B34: =B32/B33 -> 8366.2121 | C34: =C32/C33 -> 5446.8197 | D34: =D32/D33 -> 8010.75 | E34: =E32/E33 -> 7302.7143 | F34: =F32/F33 -> 9871.7083 | G34: =G32/G33 -> 7266.0233
A35: CPL USD | G35: =G34/B1 -> 5.3309049
A36: Reuniones | B36: 7 | C36: 6 | D36: 3 | E36: 5 | F36: 2 | G36: =SUM(B36:D36) -> 16
A37: CPR | B37: =B32/B36 -> 118322.14 | C37: =C32/C36 -> 110752 | D37: =D32/D36 -> 170896 | E37: =E32/E36 -> 112461.8 | G37: =G32/G36 -> 175292.81
A38: CPR USD | G38: =G37/B1 -> 128.60808
A39: % Lead a reunión | B39: =B36/B33 -> 0.070707071 | C39: =C36/C33 -> 0.049180328 | D39: =D36/D33 -> 0.046875 | E39: =E36/E33 -> 0.064935065 | G39: =G36/G33 -> 0.041450777
A40: Cierres | B40: 0 | C40: 0 | D40: 0 | G40: 1
A41: CP_CIERRE | G41: =G32/G40 -> 2804685
A42: CPC USD | G42: =G41/B1 -> 2057.7293
A43: % lead a cierre
...

Sheet Julio_25
H1: % DEL MES | I1: =15/30 -> 0.5
A2: TOTALES
A3: Métrica / fecha | B3: 1/7 al 7/7 | C3: 08/07 al 14/07 | D3: 15/07 al 21/07 | E3: 22/07 al 28/07 | F3: 29/07 al 31/07 | G3: TOTAL | H3: OBJETIVO | I3: % DE LOGRO | K3: LECTURAS SEMANA 1
A4: Inversión total | B4: =B16+B29+B42+B55+B67+B80+B106+B119 -> 2188442 | C4: =C16+C29+C42+C55+C67+C80+C106+C119 -> 2239352 | D4: =D16+D29+D42+D55+D67+D80+D106+D119 -> 2568246 | E4: =E16+E29+E42+E55+E67+E80+E106+E119 -> 2250781 | F4: =F16+F29+F42+F55+F67+F80+F106+F119 -> 1016537 | G4: =B4+C4 -> 4427794 | H4: 7500000 | I4: =G4/H4 -> 0.59037253
A5: Leads Ingresados | B5: 644 | C5: 370 | G5: =C5+B5 -> 1014 | H5: =H4/H6 -> 1829.2683 | I5: =G5/H5 -> 0.55432
A6: CPL | B6: =B4/B5 -> 3398.2019 | C6: =C4/C5 -> 6052.3027 | G6: =G4/G5 -> 4366.6608 | H6: 4100 | I6: =H6/G6-1 -> -0.06106743
A7: Reuniones | B7: 36 | C7: 43 | G7: =B7+C7 -> 79 | H7: =H5*H9 -> 128.04878 | I7: =G7/H7 -> 0.61695238
A8: CPR | B8: =B4/B7 -> 60790.056 | C8: =C4/C7 -> 52077.953 | G8: =G4/G7 -> 56048.025 | H8: =H4/H7 -> 58571.429
A9: % Lead a reunión | B9: =B7/B5 -> 0.055900621 | C9: =C7/C5 -> 0.11621622 | G9: =G7/G5 -> 0.07790927 | H9: 0.07
A10: Cierres | B10: 0 | C10: 0
A11: Costo por Cierre
A12: % lead a cierre
A14: CORRALONES
A15: Métrica / fecha | B15: 1/7 al 7/7 | C15: 08/07 al 14/07 | D15: 15/07 al 21/07 | E15: 22/07 al 28/07 | F15: 29/07 al 31/07 | G15: TOTAL | H15: OBJETIVO | K15: LECTURAS SEMANA 2
A16: Inversión total | B16: 281436 | C16: 356040 | D16: 410591 | E16: 548256 | F16: 236776
A17: Leads Ingresados | B17: 644 | C17: 370
A18: CPL | B18: =B16/B17 -> 437.01242 | C18: =C16/C17 -> 962.27027
A19: Reuniones | B19: 36 | C19: 43
A20: CPR | B20: =B16/B19 -> 7817.6667 | C20: =C16/C19 -> 8280
A21: % Lead a reunión | B21: =B19/B17 -> 0.055900621 | C21: =C19/C17 -> 0.11621622
A22: Cierres | B22: 0 | C22: 0
A23: CP_CIERRE
A24: % lead a cierre
A27: DISTRIBUIDORA
A28: Métrica / fecha | B28: 1/7 al 7/7 | C28: 08/07 al 14/07 | D28: 15/07 al 21/07 | E28: 22/07 al 28/07 | F28: 29/07 al 31/07 | G28: TOTAL | H28: OBJETIVO | K28: LECTURAS SEMANA 3
A29: Inversión total | B29: 675715 | C29: 652485 | D29: 803126 | E29: 894914 | F29: 382585
A30: Leads Ingresados | B30: 644 | C30: 370
A31: CPL | B31: =B29/B30 -> 1049.2469 | C31: =C29/C30 -> 1763.473
A32: Reuniones | B32: 36 | C32: 43
A33: CPR | B33: =B29/B32 -> 18769.861 | C33: =C29/C32 -> 15174.07
A34: % Lead a reunión | B34: =B32/B30 -> 0.055900621 | C34: =C32/C30 -> 0.11621622
A35: Cierres | B35: 0 | C35: 0
A36: CP_CIERRE
A37: % lead a cierre
A40: CARNICERIA
A41: Métrica / fecha | B41: 1/7 al 7/7 | C41: 08/07 al 14/07 | D41: 15/07 al 21/07 | E41: 22/07 al 28/07 | F41: 29/07 al 31/07 | G41: TOTAL | H41: OBJETIVO | K41: LECTURAS SEMANA 4
A42: Inversión total | B42: 368239 | C42: 359606 | D42: 438254 | E42: 580324 | F42: 261629
A43: Leads Ingresados | B43: 644 | C43: 370
A44: CPL | B44: =B42/B43 -> 571.79969 | C44: =C42/C43 -> 971.90811
A45: Reuniones | B45: 36 | C45: 43
...

Sheet Hoja 4
A1: TOTALES
A2: Métrica / fecha | B2: agosto
A3: Inversión total | B3: 100
A4: Leads Ingresados | B4: =B16+B29+B42+B55+B67+B80+B93+B106 -> 0
A5: CPL | B5: =B3/B4 -> #DIV/0!
A6: Reuniones | B6: =B18+B31+B44+B57+B69+B82+B95+B108 -> 0
A7: CPR | B7: =B3/B6 -> #DIV/0!
A8: % Lead a reunión | B8: =B6/B4 -> #DIV/0!
A9: Cierres | B9: 0
A10: Costo por Cierre
A11: % lead a cierre

Sheet Junio_25
A1: TOTALES
A2: Métrica / fecha | B2: 01/08 al 07/08 | C2: 08/08 al 15/08 | D2: 16/08 al 23/08 | E2: 23/08 al 31/08 | F2: TOTAL | G2: OBJETIVO | I2: LECTURAS SEMANA 1
A3: Inversión total | B3: 2100000 | C3: 1700000
A4: Leads Ingresados | B4: 644 | C4: 370
A5: CPL | B5: =B3/B4 -> 3260.8696 | C5: =C3/C4 -> 4594.5946
A6: Reuniones | B6: 36 | C6: 43
A7: CPR | B7: =B3/B6 -> 58333.333 | C7: =C3/C6 -> 39534.884
A8: % Lead a reunión | B8: =B6/B4 -> 0.055900621 | C8: =C6/C4 -> 0.11621622
A9: Cierres | B9: 0 | C9: 0
A10: Costo por Cierre
A11: % lead a cierre
A13: CORRALONES
A14: Métrica / fecha | B14: 01/08 al 07/08 | C14: 08/08 al 15/08 | D14: 16/08 al 23/08 | E14: 23/08 al 31/08 | F14: TOTAL | G14: OBJETIVO | I14: LECTURAS SEMANA 2
A15: Inversión total | B15: 2100000 | C15: 1700000
A16: Leads Ingresados | B16: 644 | C16: 370
A17: CPL | B17: =B15/B16 -> 3260.8696 | C17: =C15/C16 -> 4594.5946
A18: Reuniones | B18: 36 | C18: 43
A19: CPR | B19: =B15/B18 -> 58333.333 | C19: =C15/C18 -> 39534.884
A20: % Lead a reunión | B20: =B18/B16 -> 0.055900621 | C20: =C18/C16 -> 0.11621622
A21: Cierres | B21: 0 | C21: 0
A22: CP_CIERRE
A23: % lead a cierre
A26: DISTRIBUIDORA
A27: Métrica / fecha | B27: 01/08 al 07/08 | C27: 08/08 al 15/08 | D27: 16/08 al 23/08 | E27: 23/08 al 31/08 | F27: TOTAL | G27: OBJETIVO | I27: LECTURAS SEMANA 3
A28: Inversión total | B28: 2100000 | C28: 1700000
A29: Leads Ingresados | B29: 644 | C29: 370
A30: CPL | B30: =B28/B29 -> 3260.8696 | C30: =C28/C29 -> 4594.5946
A31: Reuniones | B31: 36 | C31: 43
A32: CPR | B32: =B28/B31 -> 58333.333 | C32: =C28/C31 -> 39534.884
A33: % Lead a reunión | B33: =B31/B29 -> 0.055900621 | C33: =C31/C29 -> 0.11621622
A34: Cierres | B34: 0 | C34: 0
A35: CP_CIERRE
A36: % lead a cierre
A39: CARNICERIA
A40: Métrica / fecha | B40: 01/08 al 07/08 | C40: 08/08 al 15/08 | D40: 16/08 al 23/08 | E40: 23/08 al 31/08 | F40: TOTAL | G40: OBJETIVO | I40: LECTURAS SEMANA 4
A41: Inversión total | B41: 2100000 | C41: 1700000
A42: Leads Ingresados | B42: 644 | C42: 370
A43: CPL | B43: =B41/B42 -> 3260.8696 | C43: =C41/C42 -> 4594.5946
A44: Reuniones | B44: 36 | C44: 43
A45: CPR | B45: =B41/B44 -> 58333.333 | C45: =C41/C44 -> 39534.884
...
